<?xml version="1.0" ?>
<robot name="hero3" xmlns:xacro="http://www.ros.org/wiki/xacro">

<xacro:include filename="$(find rover_description)/urdf/hero_3ws/materials.xacro" />
<!-- <xacro:include filename="$(find rover_description)/urdf/hero_3wheel_1hand.trans" /> -->
<xacro:include filename="$(find rover_description)/urdf/hero_3ws/moonbot_hero.gazebo" />
<link name="base_link">
  <inertial>
    <origin xyz="-0.14167337236992036 -9.15348508101488e-10 0.19562270994262726" rpy="0 0 0"/>
    <mass value="375.11988568950204"/>
    <inertia ixx="7.759179" iyy="7.759179" izz="7.759179" ixy="0.0" iyz="0.0" ixz="0.0"/>
  </inertial>
  <visual>
    <origin xyz="0 0 0" rpy="0 0 0"/>
    <geometry>
      <mesh filename="package://rover_description/meshes/hero_3ws/base_link.stl" scale="0.001 0.001 0.001"/>
    </geometry>
    <material name="silver"/>
  </visual>
  <collision>
    <origin xyz="0 0 0" rpy="0 0 0"/>
    <geometry>
      <mesh filename="package://rover_description/meshes/hero_3ws/base_link.stl" scale="0.001 0.001 0.001"/>
    </geometry>
  </collision>
</link>

<link name="Leg1_Hip_2">
  <inertial>
    <origin xyz="0.004852130725744815 -0.008404600121159872 -0.0034310846199309963" rpy="0 0 0"/>
    <mass value="4.8666362605472635"/>
    <inertia ixx="0.011675" iyy="0.011856" izz="0.006228" ixy="-0.000156" iyz="0.002001" ixz="-0.001155"/>
  </inertial>
  <visual>
    <origin xyz="0.048782 0.161811 -0.129376" rpy="0 0 0"/>
    <geometry>
      <mesh filename="package://rover_description/meshes/hero_3ws/Leg1_Hip_2.stl" scale="0.001 0.001 0.001"/>
    </geometry>
    <material name="silver"/>
  </visual>
  <collision>
    <origin xyz="0.048782 0.161811 -0.129376" rpy="0 0 0"/>
    <geometry>
      <mesh filename="package://rover_description/meshes/hero_3ws/Leg1_Hip_2.stl" scale="0.001 0.001 0.001"/>
    </geometry>
  </collision>
</link>

<link name="Leg1_RollLink1_2">
  <inertial>
    <origin xyz="0.028955935722407476 -0.05944423084954953 -0.023320043829968454" rpy="0 0 0"/>
    <mass value="9.373863502530105"/>
    <inertia ixx="0.020085" iyy="0.014911" izz="0.020412" ixy="0.002867" iyz="-0.002484" ixz="0.001105"/>
  </inertial>
  <visual>
    <origin xyz="0.029926 0.194471 -0.116043" rpy="0 0 0"/>
    <geometry>
      <mesh filename="package://rover_description/meshes/hero_3ws/Leg1_RollLink1_2.stl" scale="0.001 0.001 0.001"/>
    </geometry>
    <material name="silver"/>
  </visual>
  <collision>
    <origin xyz="0.029926 0.194471 -0.116043" rpy="0 0 0"/>
    <geometry>
      <mesh filename="package://rover_description/meshes/hero_3ws/Leg1_RollLink1_2.stl" scale="0.001 0.001 0.001"/>
    </geometry>
  </collision>
</link>

<link name="Leg1_PitchLink1_2">
  <inertial>
    <origin xyz="0.026550979767143403 -0.005348965716956755 0.024913183111734724" rpy="0 0 0"/>
    <mass value="1.1768921510936396"/>
    <inertia ixx="0.001702" iyy="0.002485" izz="0.002124" ixy="0.000101" iyz="-0.000171" ixz="-0.000527"/>
  </inertial>
  <visual>
    <origin xyz="0.026086 0.30112 -0.082709" rpy="0 0 0"/>
    <geometry>
      <mesh filename="package://rover_description/meshes/hero_3ws/Leg1_PitchLink1_2.stl" scale="0.001 0.001 0.001"/>
    </geometry>
    <material name="silver"/>
  </visual>
  <collision>
    <origin xyz="0.026086 0.30112 -0.082709" rpy="0 0 0"/>
    <geometry>
      <mesh filename="package://rover_description/meshes/hero_3ws/Leg1_PitchLink1_2.stl" scale="0.001 0.001 0.001"/>
    </geometry>
  </collision>
</link>

<link name="Leg1_RollLink2_2">
  <inertial>
    <origin xyz="0.06866049506025869 -0.10507937938346701 0.17753285508092348" rpy="0 0 0"/>
    <mass value="25.903618237357847"/>
    <inertia ixx="0.420452" iyy="0.379605" izz="0.174616" ixy="0.070601" iyz="0.165052" ixz="-0.1227"/>
  </inertial>
  <visual>
    <origin xyz="-0.035874 0.304437 -0.129805" rpy="0 0 0"/>
    <geometry>
      <mesh filename="package://rover_description/meshes/hero_3ws/Leg1_RollLink2_2.stl" scale="0.001 0.001 0.001"/>
    </geometry>
    <material name="silver"/>
  </visual>
  <collision>
    <origin xyz="-0.035874 0.304437 -0.129805" rpy="0 0 0"/>
    <geometry>
      <mesh filename="package://rover_description/meshes/hero_3ws/Leg1_RollLink2_2.stl" scale="0.001 0.001 0.001"/>
    </geometry>
  </collision>
</link>

<link name="Leg1_Ankle_2">
  <inertial>
    <origin xyz="3.971685119674717e-08 3.282325534703645e-07 -0.02970627141838429" rpy="0 0 0"/>
    <mass value="4.8666362605472635"/>
    <inertia ixx="0.005411" iyy="0.011585" izz="0.012763" ixy="-0.0" iyz="-0.0" ixz="0.0"/>
  </inertial>
  <visual>
    <origin xyz="-0.387924 0.6809 0.030367" rpy="0 0 0"/>
    <geometry>
      <mesh filename="package://rover_description/meshes/hero_3ws/Leg1_Ankle_2.stl" scale="0.001 0.001 0.001"/>
    </geometry>
    <material name="silver"/>
  </visual>
  <collision>
    <origin xyz="-0.387924 0.6809 0.030367" rpy="0 0 0"/>
    <geometry>
      <mesh filename="package://rover_description/meshes/hero_3ws/Leg1_Ankle_2.stl" scale="0.001 0.001 0.001"/>
    </geometry>
  </collision>
</link>

<link name="Leg1_WheelBody_2">
  <inertial>
    <origin xyz="3.971685114123602e-08 3.2823255047276234e-07 -0.09099983850517727" rpy="0 0 0"/>
    <mass value="31.73897478389843"/>
    <inertia ixx="0.129347" iyy="0.147573" izz="0.129347" ixy="0.0" iyz="-0.0" ixz="-0.0"/>
  </inertial>
  <visual>
    <origin xyz="-0.387924 0.6809 0.070367" rpy="0 0 0"/>
    <geometry>
      <mesh filename="package://rover_description/meshes/hero_3ws/Leg1_WheelBody_2.stl" scale="0.001 0.001 0.001"/>
    </geometry>
    <material name="silver"/>
  </visual>
  <collision>
    <origin xyz="-0.387924 0.6809 0.070367" rpy="0 0 0"/>
    <geometry>
      <mesh filename="package://rover_description/meshes/hero_3ws/Leg1_WheelBody_2.stl" scale="0.001 0.001 0.001"/>
    </geometry>
  </collision>
</link>

<link name="Leg1_Wheel1_2">
  <inertial>
    <origin xyz="4.012830689958946e-08 0.05135077156296519 1.6149481824045964e-07" rpy="0 0 0"/>
    <mass value="25.69936736300387"/>
    <inertia ixx="0.305243" iyy="0.555086" izz="0.305243" ixy="0.0" iyz="-0.0" ixz="-0.0"/>
  </inertial>
  <visual>
    <origin xyz="-0.387924 0.6109 0.161367" rpy="0 0 0"/>
    <geometry>
      <mesh filename="package://rover_description/meshes/hero_3ws/Leg1_Wheel1_2.stl" scale="0.001 0.001 0.001"/>
    </geometry>
    <material name="silver"/>
  </visual>
  <collision>
    <origin xyz="-0.387924 0.6109 0.161367" rpy="0 0 0"/>
    <geometry>
      <mesh filename="package://rover_description/meshes/hero_3ws/Leg1_Wheel1_2.stl" scale="0.001 0.001 0.001"/>
    </geometry>
  </collision>
</link>

<link name="Leg1_Wheel2_2">
  <inertial>
    <origin xyz="3.930539771435093e-08 -0.05135011509786369 1.6149482745531074e-07" rpy="0 0 0"/>
    <mass value="25.69936736300387"/>
    <inertia ixx="0.305243" iyy="0.555086" izz="0.305243" ixy="0.0" iyz="-0.0" ixz="0.0"/>
  </inertial>
  <visual>
    <origin xyz="-0.387924 0.7509 0.161367" rpy="0 0 0"/>
    <geometry>
      <mesh filename="package://rover_description/meshes/hero_3ws/Leg1_Wheel2_2.stl" scale="0.001 0.001 0.001"/>
    </geometry>
    <material name="silver"/>
  </visual>
  <collision>
    <origin xyz="-0.387924 0.7509 0.161367" rpy="0 0 0"/>
    <geometry>
      <mesh filename="package://rover_description/meshes/hero_3ws/Leg1_Wheel2_2.stl" scale="0.001 0.001 0.001"/>
    </geometry>
  </collision>
</link>

<link name="Arm_Hip_2">
  <inertial>
    <origin xyz="-1.1367328642264418e-07 4.4062077866755455e-07 0.01029382547724339" rpy="0 0 0"/>
    <mass value="4.8666362605472635"/>
    <inertia ixx="0.005411" iyy="0.011585" izz="0.012763" ixy="-0.0" iyz="-0.0" ixz="0.0"/>
  </inertial>
  <visual>
    <origin xyz="0.141408 -0.000459 -0.393612" rpy="0 0 0"/>
    <geometry>
      <mesh filename="package://rover_description/meshes/hero_3ws/Arm_Hip_2.stl" scale="0.001 0.001 0.001"/>
    </geometry>
    <material name="silver"/>
  </visual>
  <collision>
    <origin xyz="0.141408 -0.000459 -0.393612" rpy="0 0 0"/>
    <geometry>
      <mesh filename="package://rover_description/meshes/hero_3ws/Arm_Hip_2.stl" scale="0.001 0.001 0.001"/>
    </geometry>
  </collision>
</link>

<link name="Arm_RollLink1_2">
  <inertial>
    <origin xyz="-1.0693622759516686e-07 0.004647608588767994 0.0699597205126613" rpy="0 0 0"/>
    <mass value="9.373863502530105"/>
    <inertia ixx="0.021368" iyy="0.021275" izz="0.012766" ixy="0.0" iyz="-0.000856" ixz="0.0"/>
  </inertial>
  <visual>
    <origin xyz="0.141408 -0.000459 -0.433612" rpy="0 0 0"/>
    <geometry>
      <mesh filename="package://rover_description/meshes/hero_3ws/Arm_RollLink1_2.stl" scale="0.001 0.001 0.001"/>
    </geometry>
    <material name="silver"/>
  </visual>
  <collision>
    <origin xyz="0.141408 -0.000459 -0.433612" rpy="0 0 0"/>
    <geometry>
      <mesh filename="package://rover_description/meshes/hero_3ws/Arm_RollLink1_2.stl" scale="0.001 0.001 0.001"/>
    </geometry>
  </collision>
</link>

<link name="Arm_PitchLink1_2">
  <inertial>
    <origin xyz="0.020364201640821783 -0.01931832871808176 0.02426950420278251" rpy="0 0 0"/>
    <mass value="1.1768921510936396"/>
    <inertia ixx="0.002161" iyy="0.002042" izz="0.002109" ixy="0.000429" iyz="0.000511" ixz="-0.000147"/>
  </inertial>
  <visual>
    <origin xyz="0.141408 -0.050459 -0.533612" rpy="0 0 0"/>
    <geometry>
      <mesh filename="package://rover_description/meshes/hero_3ws/Arm_PitchLink1_2.stl" scale="0.001 0.001 0.001"/>
    </geometry>
    <material name="silver"/>
  </visual>
  <collision>
    <origin xyz="0.141408 -0.050459 -0.533612" rpy="0 0 0"/>
    <geometry>
      <mesh filename="package://rover_description/meshes/hero_3ws/Arm_PitchLink1_2.stl" scale="0.001 0.001 0.001"/>
    </geometry>
  </collision>
</link>

<link name="Arm_RollLink2_2">
  <inertial>
    <origin xyz="0.13968261924363629 -0.007165626620847408 0.16646701617319648" rpy="0 0 0"/>
    <mass value="25.903618237357847"/>
    <inertia ixx="0.289462" iyy="0.471503" izz="0.213708" ixy="0.019666" iyz="0.023437" ixz="-0.214812"/>
  </inertial>
  <visual>
    <origin xyz="0.102841 -0.004459 -0.579575" rpy="0 0 0"/>
    <geometry>
      <mesh filename="package://rover_description/meshes/hero_3ws/Arm_RollLink2_2.stl" scale="0.001 0.001 0.001"/>
    </geometry>
    <material name="silver"/>
  </visual>
  <collision>
    <origin xyz="0.102841 -0.004459 -0.579575" rpy="0 0 0"/>
    <geometry>
      <mesh filename="package://rover_description/meshes/hero_3ws/Arm_RollLink2_2.stl" scale="0.001 0.001 0.001"/>
    </geometry>
  </collision>
</link>

<link name="Arm_PitchLink2_2">
  <inertial>
    <origin xyz="0.14216759640201995 0.007166505686281352 -0.17140634825331957" rpy="0 0 0"/>
    <mass value="25.903618237357847"/>
    <inertia ixx="0.291912" iyy="0.471503" izz="0.211258" ixy="0.019532" iyz="-0.023549" ixz="0.214365"/>
  </inertial>
  <visual>
    <origin xyz="-0.179986 -0.004459 -0.916634" rpy="0 0 0"/>
    <geometry>
      <mesh filename="package://rover_description/meshes/hero_3ws/Arm_PitchLink2_2.stl" scale="0.001 0.001 0.001"/>
    </geometry>
    <material name="silver"/>
  </visual>
  <collision>
    <origin xyz="-0.179986 -0.004459 -0.916634" rpy="0 0 0"/>
    <geometry>
      <mesh filename="package://rover_description/meshes/hero_3ws/Arm_PitchLink2_2.stl" scale="0.001 0.001 0.001"/>
    </geometry>
  </collision>
</link>

<link name="Arm_RollLink3_2">
  <inertial>
    <origin xyz="0.04548945843263069 0.004521527467021694 -0.05316162906682431" rpy="0 0 0"/>
    <mass value="9.373863502530105"/>
    <inertia ixx="0.017664" iyy="0.02128" izz="0.016464" ixy="-0.000548" iyz="0.000628" ixz="0.004261"/>
  </inertial>
  <visual>
    <origin xyz="-0.460884 -0.004459 -0.577966" rpy="0 0 0"/>
    <geometry>
      <mesh filename="package://rover_description/meshes/hero_3ws/Arm_RollLink3_2.stl" scale="0.001 0.001 0.001"/>
    </geometry>
    <material name="silver"/>
  </visual>
  <collision>
    <origin xyz="-0.460884 -0.004459 -0.577966" rpy="0 0 0"/>
    <geometry>
      <mesh filename="package://rover_description/meshes/hero_3ws/Arm_RollLink3_2.stl" scale="0.001 0.001 0.001"/>
    </geometry>
  </collision>
</link>

<link name="Arm_PitchLink3_2">
  <inertial>
    <origin xyz="0.023333454129213282 -0.022514635765186038 -0.017402008886948983" rpy="0 0 0"/>
    <mass value="1.1768921510936396"/>
    <inertia ixx="0.002296" iyy="0.001883" izz="0.002132" ixy="0.000527" iyz="-0.000367" ixz="0.000123"/>
  </inertial>
  <visual>
    <origin xyz="-0.533628 -0.053103 -0.508381" rpy="0 0 0"/>
    <geometry>
      <mesh filename="package://rover_description/meshes/hero_3ws/Arm_PitchLink3_2.stl" scale="0.001 0.001 0.001"/>
    </geometry>
    <material name="silver"/>
  </visual>
  <collision>
    <origin xyz="-0.533628 -0.053103 -0.508381" rpy="0 0 0"/>
    <geometry>
      <mesh filename="package://rover_description/meshes/hero_3ws/Arm_PitchLink3_2.stl" scale="0.001 0.001 0.001"/>
    </geometry>
  </collision>
</link>

<link name="Arm_Gripper_2">
  <inertial>
    <origin xyz="0.02609524788333506 -0.002659778112096484 -0.01394327939472062" rpy="0 0 0"/>
    <mass value="4.8666362605472635"/>
    <inertia ixx="0.011628" iyy="0.010166" izz="0.007966" ixy="0.00102" iyz="0.002404" ixz="-0.002318"/>
  </inertial>
  <visual>
    <origin xyz="-0.576209 -0.002185 -0.474216" rpy="0 0 0"/>
    <geometry>
      <mesh filename="package://rover_description/meshes/hero_3ws/Arm_Gripper_2.stl" scale="0.001 0.001 0.001"/>
    </geometry>
    <material name="silver"/>
  </visual>
  <collision>
    <origin xyz="-0.576209 -0.002185 -0.474216" rpy="0 0 0"/>
    <geometry>
      <mesh filename="package://rover_description/meshes/hero_3ws/Arm_Gripper_2.stl" scale="0.001 0.001 0.001"/>
    </geometry>
  </collision>
</link>

<link name="Leg2_Hip_2">
  <inertial>
    <origin xyz="0.004852650421350864 0.008404598290472964 -0.0034308164668667984" rpy="0 0 0"/>
    <mass value="4.8666362605472635"/>
    <inertia ixx="0.011675" iyy="0.011856" izz="0.006228" ixy="0.000156" iyz="-0.002001" ixz="-0.001155"/>
  </inertial>
  <visual>
    <origin xyz="0.048252 -0.161811 -0.130126" rpy="0 0 0"/>
    <geometry>
      <mesh filename="package://rover_description/meshes/hero_3ws/Leg2_Hip_2.stl" scale="0.001 0.001 0.001"/>
    </geometry>
    <material name="silver"/>
  </visual>
  <collision>
    <origin xyz="0.048252 -0.161811 -0.130126" rpy="0 0 0"/>
    <geometry>
      <mesh filename="package://rover_description/meshes/hero_3ws/Leg2_Hip_2.stl" scale="0.001 0.001 0.001"/>
    </geometry>
  </collision>
</link>

<link name="Leg2_RollLink1_2">
  <inertial>
    <origin xyz="0.036560061839939234 0.054496153137137265 -0.02468691356582481" rpy="0 0 0"/>
    <mass value="9.373863502530105"/>
    <inertia ixx="0.018779" iyy="0.016393" izz="0.020236" ixy="-0.003581" iyz="0.00237" ixz="0.001712"/>
  </inertial>
  <visual>
    <origin xyz="0.029396 -0.194471 -0.116793" rpy="0 0 0"/>
    <geometry>
      <mesh filename="package://rover_description/meshes/hero_3ws/Leg2_RollLink1_2.stl" scale="0.001 0.001 0.001"/>
    </geometry>
    <material name="silver"/>
  </visual>
  <collision>
    <origin xyz="0.029396 -0.194471 -0.116793" rpy="0 0 0"/>
    <geometry>
      <mesh filename="package://rover_description/meshes/hero_3ws/Leg2_RollLink1_2.stl" scale="0.001 0.001 0.001"/>
    </geometry>
  </collision>
</link>

<link name="Leg2_PitchLink1_2">
  <inertial>
    <origin xyz="0.001276674304898473 0.022577155307953956 0.029031282679143858" rpy="0 0 0"/>
    <mass value="1.1768921510936396"/>
    <inertia ixx="0.002601" iyy="0.001884" izz="0.001826" ixy="5.9e-05" iyz="-0.00047" ixz="0.000245"/>
  </inertial>
  <visual>
    <origin xyz="-0.05628 -0.247865 -0.068746" rpy="0 0 0"/>
    <geometry>
      <mesh filename="package://rover_description/meshes/hero_3ws/Leg2_PitchLink1_2.stl" scale="0.001 0.001 0.001"/>
    </geometry>
    <material name="silver"/>
  </visual>
  <collision>
    <origin xyz="-0.05628 -0.247865 -0.068746" rpy="0 0 0"/>
    <geometry>
      <mesh filename="package://rover_description/meshes/hero_3ws/Leg2_PitchLink1_2.stl" scale="0.001 0.001 0.001"/>
    </geometry>
  </collision>
</link>

<link name="Leg2_RollLink2_2">
  <inertial>
    <origin xyz="0.11536631255126499 0.08402778443626557 0.16402371648953915" rpy="0 0 0"/>
    <mass value="25.903618237357847"/>
    <inertia ixx="0.359155" iyy="0.396878" izz="0.218639" ixy="-0.093708" iyz="-0.137021" ixz="-0.168099"/>
  </inertial>
  <visual>
    <origin xyz="-0.04822 -0.298225 -0.127626" rpy="0 0 0"/>
    <geometry>
      <mesh filename="package://rover_description/meshes/hero_3ws/Leg2_RollLink2_2.stl" scale="0.001 0.001 0.001"/>
    </geometry>
    <material name="silver"/>
  </visual>
  <collision>
    <origin xyz="-0.04822 -0.298225 -0.127626" rpy="0 0 0"/>
    <geometry>
      <mesh filename="package://rover_description/meshes/hero_3ws/Leg2_RollLink2_2.stl" scale="0.001 0.001 0.001"/>
    </geometry>
  </collision>
</link>

<link name="Leg1_PitchRollLink3_2">
  <inertial>
    <origin xyz="0.09526691735033144 -0.07291277983399935 -0.18775362061459083" rpy="0 0 0"/>
    <mass value="25.903618237357847"/>
    <inertia ixx="0.361605" iyy="0.442101" izz="0.170967" ixy="0.05879" iyz="-0.093258" ixz="0.181916"/>
  </inertial>
  <visual>
    <origin xyz="-0.164283 0.526848 -0.487079" rpy="0 0 0"/>
    <geometry>
      <mesh filename="package://rover_description/meshes/hero_3ws/Leg1_PitchRollLink3_2.stl" scale="0.001 0.001 0.001"/>
    </geometry>
    <material name="silver"/>
  </visual>
  <collision>
    <origin xyz="-0.164283 0.526848 -0.487079" rpy="0 0 0"/>
    <geometry>
      <mesh filename="package://rover_description/meshes/hero_3ws/Leg1_PitchRollLink3_2.stl" scale="0.001 0.001 0.001"/>
    </geometry>
  </collision>
</link>

<link name="Leg1_SteeringLink3_2">
  <inertial>
    <origin xyz="0.025452066741113055 0.037537947195719124 -0.030040376382966333" rpy="0 0 0"/>
    <mass value="9.373863502530105"/>
    <inertia ixx="0.021338" iyy="0.021304" izz="0.012766" ixy="-4.3e-05" iyz="0.000708" ixz="0.00048"/>
  </inertial>
  <visual>
    <origin xyz="-0.359864 0.722284 -0.069633" rpy="0 0 0"/>
    <geometry>
      <mesh filename="package://rover_description/meshes/hero_3ws/Leg1_SteeringLink3_2.stl" scale="0.001 0.001 0.001"/>
    </geometry>
    <material name="silver"/>
  </visual>
  <collision>
    <origin xyz="-0.359864 0.722284 -0.069633" rpy="0 0 0"/>
    <geometry>
      <mesh filename="package://rover_description/meshes/hero_3ws/Leg1_SteeringLink3_2.stl" scale="0.001 0.001 0.001"/>
    </geometry>
  </collision>
</link>

<link name="Leg2_PitchLink2_2">
  <inertial>
    <origin xyz="0.09835565893065884 0.09753828498579797 -0.17451581344279726" rpy="0 0 0"/>
    <mass value="25.903618237357847"/>
    <inertia ixx="0.409621" iyy="0.355924" izz="0.209128" ixy="-0.086547" iyz="0.174237" ixz="0.126552"/>
  </inertial>
  <visual>
    <origin xyz="-0.291111 -0.45733 -0.458216" rpy="0 0 0"/>
    <geometry>
      <mesh filename="package://rover_description/meshes/hero_3ws/Leg2_PitchLink2_2.stl" scale="0.001 0.001 0.001"/>
    </geometry>
    <material name="silver"/>
  </visual>
  <collision>
    <origin xyz="-0.291111 -0.45733 -0.458216" rpy="0 0 0"/>
    <geometry>
      <mesh filename="package://rover_description/meshes/hero_3ws/Leg2_PitchLink2_2.stl" scale="0.001 0.001 0.001"/>
    </geometry>
  </collision>
</link>

<link name="Leg2_RollLink3_2">
  <inertial>
    <origin xyz="0.034928703545287376 -0.008693995099677387 -0.02131668458968726" rpy="0 0 0"/>
    <mass value="1.1768921510936396"/>
    <inertia ixx="0.001662" iyy="0.002513" izz="0.002137" ixy="6.2e-05" iyz="-0.000263" ixz="0.000465"/>
  </inertial>
  <visual>
    <origin xyz="-0.47637 -0.660815 -0.11489" rpy="0 0 0"/>
    <geometry>
      <mesh filename="package://rover_description/meshes/hero_3ws/Leg2_RollLink3_2.stl" scale="0.001 0.001 0.001"/>
    </geometry>
    <material name="silver"/>
  </visual>
  <collision>
    <origin xyz="-0.47637 -0.660815 -0.11489" rpy="0 0 0"/>
    <geometry>
      <mesh filename="package://rover_description/meshes/hero_3ws/Leg2_RollLink3_2.stl" scale="0.001 0.001 0.001"/>
    </geometry>
  </collision>
</link>

<link name="Leg2_SteeringLink3_2">
  <inertial>
    <origin xyz="-0.03353560981696624 0.030532344052161542 -0.030040376383004497" rpy="0 0 0"/>
    <mass value="9.373863502530105"/>
    <inertia ixx="0.021317" iyy="0.021326" izz="0.012766" ixy="4.6e-05" iyz="0.000576" ixz="-0.000633"/>
  </inertial>
  <visual>
    <origin xyz="-0.539241 -0.652631 -0.069633" rpy="0 0 0"/>
    <geometry>
      <mesh filename="package://rover_description/meshes/hero_3ws/Leg2_SteeringLink3_2.stl" scale="0.001 0.001 0.001"/>
    </geometry>
    <material name="silver"/>
  </visual>
  <collision>
    <origin xyz="-0.539241 -0.652631 -0.069633" rpy="0 0 0"/>
    <geometry>
      <mesh filename="package://rover_description/meshes/hero_3ws/Leg2_SteeringLink3_2.stl" scale="0.001 0.001 0.001"/>
    </geometry>
  </collision>
</link>

<link name="Leg2_Ankle_2">
  <inertial>
    <origin xyz="5.414030357364652e-08 -1.1559742862932154e-07 -0.029706271418423195" rpy="0 0 0"/>
    <mass value="4.8666362605472635"/>
    <inertia ixx="0.005412" iyy="0.011584" izz="0.012763" ixy="-8e-05" iyz="0.0" ixz="0.0"/>
  </inertial>
  <visual>
    <origin xyz="-0.502269 -0.686292 0.030367" rpy="0 0 0"/>
    <geometry>
      <mesh filename="package://rover_description/meshes/hero_3ws/Leg2_Ankle_2.stl" scale="0.001 0.001 0.001"/>
    </geometry>
    <material name="silver"/>
  </visual>
  <collision>
    <origin xyz="-0.502269 -0.686292 0.030367" rpy="0 0 0"/>
    <geometry>
      <mesh filename="package://rover_description/meshes/hero_3ws/Leg2_Ankle_2.stl" scale="0.001 0.001 0.001"/>
    </geometry>
  </collision>
</link>

<link name="Leg2_WheelBody_2">
  <inertial>
    <origin xyz="5.4140303795691125e-08 -1.155974312938568e-07 -0.09099983850521635" rpy="0 0 0"/>
    <mass value="31.73897478389843"/>
    <inertia ixx="0.12935" iyy="0.14757" izz="0.129347" ixy="-0.000237" iyz="-0.0" ixz="0.0"/>
  </inertial>
  <visual>
    <origin xyz="-0.502269 -0.686292 0.070367" rpy="0 0 0"/>
    <geometry>
      <mesh filename="package://rover_description/meshes/hero_3ws/Leg2_WheelBody_2.stl" scale="0.001 0.001 0.001"/>
    </geometry>
    <material name="silver"/>
  </visual>
  <collision>
    <origin xyz="-0.502269 -0.686292 0.070367" rpy="0 0 0"/>
    <geometry>
      <mesh filename="package://rover_description/meshes/hero_3ws/Leg2_WheelBody_2.stl" scale="0.001 0.001 0.001"/>
    </geometry>
  </collision>
</link>

<link name="Leg2_Wheel1_2">
  <inertial>
    <origin xyz="-0.0006681072725871484 0.05134605230141531 1.6149478068716583e-07" rpy="0 0 0"/>
    <mass value="25.69936736300387"/>
    <inertia ixx="0.305285" iyy="0.555043" izz="0.305243" ixy="-0.003251" iyz="-0.0" ixz="-0.0"/>
  </inertial>
  <visual>
    <origin xyz="-0.501358 -0.756286 0.161367" rpy="0 0 0"/>
    <geometry>
      <mesh filename="package://rover_description/meshes/hero_3ws/Leg2_Wheel1_2.stl" scale="0.001 0.001 0.001"/>
    </geometry>
    <material name="silver"/>
  </visual>
  <collision>
    <origin xyz="-0.501358 -0.756286 0.161367" rpy="0 0 0"/>
    <geometry>
      <mesh filename="package://rover_description/meshes/hero_3ws/Leg2_Wheel1_2.stl" scale="0.001 0.001 0.001"/>
    </geometry>
  </collision>
</link>

<link name="Leg2_Wheel2_2">
  <inertial>
    <origin xyz="0.0006682155531912981 -0.05134628349627779 1.61494787542793e-07" rpy="0 0 0"/>
    <mass value="25.69936736300387"/>
    <inertia ixx="0.305285" iyy="0.555043" izz="0.305243" ixy="-0.003251" iyz="-0.0" ixz="-0.0"/>
  </inertial>
  <visual>
    <origin xyz="-0.50318 -0.616298 0.161367" rpy="0 0 0"/>
    <geometry>
      <mesh filename="package://rover_description/meshes/hero_3ws/Leg2_Wheel2_2.stl" scale="0.001 0.001 0.001"/>
    </geometry>
    <material name="silver"/>
  </visual>
  <collision>
    <origin xyz="-0.50318 -0.616298 0.161367" rpy="0 0 0"/>
    <geometry>
      <mesh filename="package://rover_description/meshes/hero_3ws/Leg2_Wheel2_2.stl" scale="0.001 0.001 0.001"/>
    </geometry>
  </collision>
</link>

<link name="Leg3_Hip_2">
  <inertial>
    <origin xyz="-0.009705156953495664 -4.424514854722383e-07 -0.0034310846199381018" rpy="0 0 0"/>
    <mass value="4.866636260547267"/>
    <inertia ixx="0.011946" iyy="0.011585" izz="0.006228" ixy="0.0" iyz="-0.0" ixz="0.00231"/>
  </inertial>
  <visual>
    <origin xyz="0.328251 0.000459 -0.129376" rpy="0 0 0"/>
    <geometry>
      <mesh filename="package://rover_description/meshes/hero_3ws/Leg3_Hip_2.stl" scale="0.001 0.001 0.001"/>
    </geometry>
    <material name="silver"/>
  </visual>
  <collision>
    <origin xyz="0.328251 0.000459 -0.129376" rpy="0 0 0"/>
    <geometry>
      <mesh filename="package://rover_description/meshes/hero_3ws/Leg3_Hip_2.stl" scale="0.001 0.001 0.001"/>
    </geometry>
  </collision>
</link>

<link name="Leg3_RollLink1_2">
  <inertial>
    <origin xyz="-0.06595806599200232 0.004645089806756357 -0.023320043800281007" rpy="0 0 0"/>
    <mass value="9.37386350253013"/>
    <inertia ixx="0.013721" iyy="0.021275" izz="0.020412" ixy="0.000807" iyz="0.000285" ixz="-0.002703"/>
  </inertial>
  <visual>
    <origin xyz="0.365964 0.000459 -0.116043" rpy="0 0 0"/>
    <geometry>
      <mesh filename="package://rover_description/meshes/hero_3ws/Leg3_RollLink1_2.stl" scale="0.001 0.001 0.001"/>
    </geometry>
    <material name="silver"/>
  </visual>
  <collision>
    <origin xyz="0.365964 0.000459 -0.116043" rpy="0 0 0"/>
    <geometry>
      <mesh filename="package://rover_description/meshes/hero_3ws/Leg3_RollLink1_2.stl" scale="0.001 0.001 0.001"/>
    </geometry>
  </collision>
</link>

<link name="Leg3_PitchLink1_2">
  <inertial>
    <origin xyz="-0.021074617112629535 -0.019318847530479875 0.02365510604857246" rpy="0 0 0"/>
    <mass value="1.1768921510936399"/>
    <inertia ixx="0.002152" iyy="0.002042" izz="0.002118" ixy="-0.000444" iyz="0.000498" ixz="0.000148"/>
  </inertial>
  <visual>
    <origin xyz="0.460245 -0.049539 -0.082709" rpy="0 0 0"/>
    <geometry>
      <mesh filename="package://rover_description/meshes/hero_3ws/Leg3_PitchLink1_2.stl" scale="0.001 0.001 0.001"/>
    </geometry>
    <material name="silver"/>
  </visual>
  <collision>
    <origin xyz="0.460245 -0.049539 -0.082709" rpy="0 0 0"/>
    <geometry>
      <mesh filename="package://rover_description/meshes/hero_3ws/Leg3_PitchLink1_2.stl" scale="0.001 0.001 0.001"/>
    </geometry>
  </collision>
</link>

<link name="Leg3_RollLink2_2">
  <inertial>
    <origin xyz="-0.14455748876716934 -0.007166145668826322 0.16225177791874046" rpy="0 0 0"/>
    <mass value="25.903618237355808"/>
    <inertia ixx="0.276661" iyy="0.471503" izz="0.226509" ixy="-0.020353" iyz="0.022844" ixz="0.21668"/>
  </inertial>
  <visual>
    <origin xyz="0.500158 0.000461 -0.127508" rpy="0 0 0"/>
    <geometry>
      <mesh filename="package://rover_description/meshes/hero_3ws/Leg3_RollLink2_2.stl" scale="0.001 0.001 0.001"/>
    </geometry>
    <material name="silver"/>
  </visual>
  <collision>
    <origin xyz="0.500158 0.000461 -0.127508" rpy="0 0 0"/>
    <geometry>
      <mesh filename="package://rover_description/meshes/hero_3ws/Leg3_RollLink2_2.stl" scale="0.001 0.001 0.001"/>
    </geometry>
  </collision>
</link>

<link name="Leg3_PitchLink2_2">
  <inertial>
    <origin xyz="-0.14048599057199707 0.007165987300310255 -0.17278735338975482" rpy="0 0 0"/>
    <mass value="25.903618237356838"/>
    <inertia ixx="0.296093" iyy="0.471503" izz="0.207077" ixy="-0.019301" iyz="-0.023739" ixz="-0.213537"/>
  </inertial>
  <visual>
    <origin xyz="0.792856 0.000461 -0.456032" rpy="0 0 0"/>
    <geometry>
      <mesh filename="package://rover_description/meshes/hero_3ws/Leg3_PitchLink2_2.stl" scale="0.001 0.001 0.001"/>
    </geometry>
    <material name="silver"/>
  </visual>
  <collision>
    <origin xyz="0.792856 0.000461 -0.456032" rpy="0 0 0"/>
    <geometry>
      <mesh filename="package://rover_description/meshes/hero_3ws/Leg3_PitchLink2_2.stl" scale="0.001 0.001 0.001"/>
    </geometry>
  </collision>
</link>

<link name="Leg3_RollLink3_2">
  <inertial>
    <origin xyz="-0.017234273717652293 -0.03168132929463037 -0.021196215033795027" rpy="0 0 0"/>
    <mass value="1.176892151093632"/>
    <inertia ixx="0.002188" iyy="0.001986" izz="0.002138" ixy="-0.000421" iyz="-0.000518" ixz="-0.000119"/>
  </inertial>
  <visual>
    <origin xyz="1.070431 0.000461 -0.114635" rpy="0 0 0"/>
    <geometry>
      <mesh filename="package://rover_description/meshes/hero_3ws/Leg3_RollLink3_2.stl" scale="0.001 0.001 0.001"/>
    </geometry>
    <material name="silver"/>
  </visual>
  <collision>
    <origin xyz="1.070431 0.000461 -0.114635" rpy="0 0 0"/>
    <geometry>
      <mesh filename="package://rover_description/meshes/hero_3ws/Leg3_RollLink3_2.stl" scale="0.001 0.001 0.001"/>
    </geometry>
  </collision>
</link>

<link name="Leg3_SteeringLink_2">
  <inertial>
    <origin xyz="3.531852306171146e-07 0.04535275318160254 -0.030040376382984957" rpy="0 0 0"/>
    <mass value="9.373863502530083"/>
    <inertia ixx="0.021368" iyy="0.021275" izz="0.012766" ixy="0.0" iyz="0.000856" ixz="-0.0"/>
  </inertial>
  <visual>
    <origin xyz="1.107021 0.052461 -0.069633" rpy="0 0 0"/>
    <geometry>
      <mesh filename="package://rover_description/meshes/hero_3ws/Leg3_SteeringLink_2.stl" scale="0.001 0.001 0.001"/>
    </geometry>
    <material name="silver"/>
  </visual>
  <collision>
    <origin xyz="1.107021 0.052461 -0.069633" rpy="0 0 0"/>
    <geometry>
      <mesh filename="package://rover_description/meshes/hero_3ws/Leg3_SteeringLink_2.stl" scale="0.001 0.001 0.001"/>
    </geometry>
  </collision>
</link>

<link name="Leg3_Ankle_2">
  <inertial>
    <origin xyz="3.599195499415231e-07 -7.885041453754502e-08 -0.02970627141840285" rpy="0 0 0"/>
    <mass value="4.866636260547271"/>
    <inertia ixx="0.005411" iyy="0.011585" izz="0.012763" ixy="-0.0" iyz="0.0" ixz="0.0"/>
  </inertial>
  <visual>
    <origin xyz="1.107021 0.002461 0.030367" rpy="0 0 0"/>
    <geometry>
      <mesh filename="package://rover_description/meshes/hero_3ws/Leg3_Ankle_2.stl" scale="0.001 0.001 0.001"/>
    </geometry>
    <material name="silver"/>
  </visual>
  <collision>
    <origin xyz="1.107021 0.002461 0.030367" rpy="0 0 0"/>
    <geometry>
      <mesh filename="package://rover_description/meshes/hero_3ws/Leg3_Ankle_2.stl" scale="0.001 0.001 0.001"/>
    </geometry>
  </collision>
</link>

<link name="Wheel_body_v9_2">
  <inertial>
    <origin xyz="3.599195512737907e-07 -7.885041610053087e-08 -0.09099983850519582" rpy="0 0 0"/>
    <mass value="31.73897478389851"/>
    <inertia ixx="0.129347" iyy="0.147573" izz="0.129347" ixy="0.0" iyz="-0.0" ixz="0.0"/>
  </inertial>
  <visual>
    <origin xyz="1.107021 0.002461 0.070367" rpy="0 0 0"/>
    <geometry>
      <mesh filename="package://rover_description/meshes/hero_3ws/Wheel_body_v9_2.stl" scale="0.001 0.001 0.001"/>
    </geometry>
    <material name="silver"/>
  </visual>
  <collision>
    <origin xyz="1.107021 0.002461 0.070367" rpy="0 0 0"/>
    <geometry>
      <mesh filename="package://rover_description/meshes/hero_3ws/Wheel_body_v9_2.stl" scale="0.001 0.001 0.001"/>
    </geometry>
  </collision>
</link>

<link name="Wheel_v7__1__2">
  <inertial>
    <origin xyz="3.595081004004186e-07 -0.05135052218083154 1.6149480749905187e-07" rpy="0 0 0"/>
    <mass value="25.699367363003887"/>
    <inertia ixx="0.305243" iyy="0.555086" izz="0.305243" ixy="0.0" iyz="0.0" ixz="0.0"/>
  </inertial>
  <visual>
    <origin xyz="1.107021 0.072461 0.161367" rpy="0 0 0"/>
    <geometry>
      <mesh filename="package://rover_description/meshes/hero_3ws/Wheel_v7__1__2.stl" scale="0.001 0.001 0.001"/>
    </geometry>
    <material name="silver"/>
  </visual>
  <collision>
    <origin xyz="1.107021 0.072461 0.161367" rpy="0 0 0"/>
    <geometry>
      <mesh filename="package://rover_description/meshes/hero_3ws/Wheel_v7__1__2.stl" scale="0.001 0.001 0.001"/>
    </geometry>
  </collision>
</link>

<link name="Wheel_v7_2">
  <inertial>
    <origin xyz="3.6033100170307364e-07 0.05135036447999912 1.614948001715799e-07" rpy="0 0 0"/>
    <mass value="25.699367363003883"/>
    <inertia ixx="0.305243" iyy="0.555086" izz="0.305243" ixy="0.0" iyz="0.0" ixz="-0.0"/>
  </inertial>
  <visual>
    <origin xyz="1.107021 -0.067539 0.161367" rpy="0 0 0"/>
    <geometry>
      <mesh filename="package://rover_description/meshes/hero_3ws/Wheel_v7_2.stl" scale="0.001 0.001 0.001"/>
    </geometry>
    <material name="silver"/>
  </visual>
  <collision>
    <origin xyz="1.107021 -0.067539 0.161367" rpy="0 0 0"/>
    <geometry>
      <mesh filename="package://rover_description/meshes/hero_3ws/Wheel_v7_2.stl" scale="0.001 0.001 0.001"/>
    </geometry>
  </collision>
</link>

<link name="Leg1_PitchLink2_2">
  <inertial>
    <origin xyz="-0.005449346680184375 -0.03458238104475697 -0.022899477448002095" rpy="0 0 0"/>
    <mass value="1.1768921510936396"/>
    <inertia ixx="0.002479" iyy="0.001719" izz="0.002114" ixy="2.9e-05" iyz="-0.000525" ixz="-0.000222"/>
  </inertial>
  <visual>
    <origin xyz="-0.362869 0.661495 -0.118251" rpy="0 0 0"/>
    <geometry>
      <mesh filename="package://rover_description/meshes/hero_3ws/Leg1_PitchLink2_2.stl" scale="0.001 0.001 0.001"/>
    </geometry>
    <material name="silver"/>
  </visual>
  <collision>
    <origin xyz="-0.362869 0.661495 -0.118251" rpy="0 0 0"/>
    <geometry>
      <mesh filename="package://rover_description/meshes/hero_3ws/Leg1_PitchLink2_2.stl" scale="0.001 0.001 0.001"/>
    </geometry>
  </collision>
</link>

<joint name="Rigid 33" type="fixed">
  <origin xyz="-0.048782 -0.161811 0.129376" rpy="0 0 0"/>
  <parent link="base_link"/>
  <child link="Leg1_Hip_2"/>
</joint>

<joint name="Leg1_Roll1" type="continuous">
  <origin xyz="0.018856 -0.03266 -0.013333" rpy="0 0 0"/>
  <parent link="Leg1_Hip_2"/>
  <child link="Leg1_RollLink1_2"/>
  <axis xyz="0.471405 -0.816497 -0.333333"/>
</joint>

<joint name="Leg1_Pitch1" type="continuous">
  <origin xyz="0.00384 -0.106649 -0.033334" rpy="0 0 0"/>
  <parent link="Leg1_RollLink1_2"/>
  <child link="Leg1_PitchLink1_2"/>
  <axis xyz="-0.866025 -0.5 -0.0"/>
</joint>

<joint name="Leg1_Roll2" type="continuous">
  <origin xyz="0.06196 -0.003317 0.047096" rpy="0 0 0"/>
  <parent link="Leg1_PitchLink1_2"/>
  <child link="Leg1_RollLink2_2"/>
  <axis xyz="0.291838 -0.505478 0.811987"/>
</joint>

<joint name="Leg1_Steering" type="continuous">
  <origin xyz="0.02806 0.041384 -0.1" rpy="0 0 0"/>
  <parent link="Leg1_SteeringLink3_2"/>
  <child link="Leg1_Ankle_2"/>
  <axis xyz="-0.0 -0.0 -1.0"/>
</joint>

<joint name="Rigid 41" type="fixed">
  <origin xyz="0.0 0.0 -0.04" rpy="0 0 0"/>
  <parent link="Leg1_Ankle_2"/>
  <child link="Leg1_WheelBody_2"/>
</joint>

<joint name="Leg1_Wheel1" type="continuous">
  <origin xyz="0.0 0.07 -0.091" rpy="0 0 0"/>
  <parent link="Leg1_WheelBody_2"/>
  <child link="Leg1_Wheel1_2"/>
  <axis xyz="0.0 1.0 -0.0"/>
</joint>

<joint name="Leg1_Wheel2" type="continuous">
  <origin xyz="0.0 -0.07 -0.091" rpy="0 0 0"/>
  <parent link="Leg1_WheelBody_2"/>
  <child link="Leg1_Wheel2_2"/>
  <axis xyz="-0.0 -1.0 0.0"/>
</joint>

<joint name="Rigid 44" type="fixed">
  <origin xyz="-0.141408 0.000459 0.393612" rpy="0 0 0"/>
  <parent link="base_link"/>
  <child link="Arm_Hip_2"/>
</joint>

<joint name="Arm_Roll1" type="continuous">
  <origin xyz="0.0 0.0 0.04" rpy="0 0 0"/>
  <parent link="Arm_Hip_2"/>
  <child link="Arm_RollLink1_2"/>
  <axis xyz="-0.0 0.0 1.0"/>
</joint>

<joint name="Arm_Pitch1" type="continuous">
  <origin xyz="0.0 0.05 0.1" rpy="0 0 0"/>
  <parent link="Arm_RollLink1_2"/>
  <child link="Arm_PitchLink1_2"/>
  <axis xyz="0.0 1.0 -0.0"/>
</joint>

<joint name="Arm_Roll2" type="continuous">
  <origin xyz="0.038567 -0.046 0.045963" rpy="0 0 0"/>
  <parent link="Arm_PitchLink1_2"/>
  <child link="Arm_RollLink2_2"/>
  <axis xyz="0.642788 -0.0 0.766044"/>
</joint>

<joint name="Arm_Pitch2" type="continuous">
  <origin xyz="0.282827 0.0 0.337059" rpy="0 0 0"/>
  <parent link="Arm_RollLink2_2"/>
  <child link="Arm_PitchLink2_2"/>
  <axis xyz="0.0 1.0 -0.0"/>
</joint>

<joint name="Arm_Roll3" type="continuous">
  <origin xyz="0.280898 0.0 -0.338668" rpy="0 0 0"/>
  <parent link="Arm_PitchLink2_2"/>
  <child link="Arm_RollLink3_2"/>
  <axis xyz="0.638404 -0.0 -0.769701"/>
</joint>

<joint name="Arm_Pitch3" type="continuous">
  <origin xyz="0.072744 0.048644 -0.069585" rpy="0 0 0"/>
  <parent link="Arm_RollLink3_2"/>
  <child link="Arm_PitchLink3_2"/>
  <axis xyz="0.178074 0.972869 0.147698"/>
</joint>

<joint name="Revolute 51" type="continuous">
  <origin xyz="0.042581 -0.050918 -0.034165" rpy="0 0 0"/>
  <parent link="Arm_PitchLink3_2"/>
  <child link="Arm_Gripper_2"/>
  <axis xyz="0.878454 -0.089535 -0.469363"/>
</joint>

<joint name="Rigid 52" type="fixed">
  <origin xyz="-0.048252 0.161811 0.130126" rpy="0 0 0"/>
  <parent link="base_link"/>
  <child link="Leg2_Hip_2"/>
</joint>

<joint name="Leg2_Roll1" type="continuous">
  <origin xyz="0.018856 0.03266 -0.013333" rpy="0 0 0"/>
  <parent link="Leg2_Hip_2"/>
  <child link="Leg2_RollLink1_2"/>
  <axis xyz="0.471405 0.816497 -0.333333"/>
</joint>

<joint name="Leg2_Pitch1" type="continuous">
  <origin xyz="0.085676 0.053394 -0.048047" rpy="0 0 0"/>
  <parent link="Leg2_RollLink1_2"/>
  <child link="Leg2_PitchLink1_2"/>
  <axis xyz="0.770731 -0.565125 -0.294291"/>
</joint>

<joint name="Leg2_Roll2" type="continuous">
  <origin xyz="-0.00806 0.05036 0.05888" rpy="0 0 0"/>
  <parent link="Leg2_PitchLink1_2"/>
  <child link="Leg2_RollLink2_2"/>
  <axis xyz="0.552026 0.361602 0.75134"/>
</joint>

<joint name="Leg1_Pitch2" type="continuous">
  <origin xyz="0.128409 -0.222411 0.357274" rpy="0 0 0"/>
  <parent link="Leg1_RollLink2_2"/>
  <child link="Leg1_PitchRollLink3_2"/>
  <axis xyz="-0.731438 -0.664965 -0.151067"/>
</joint>

<joint name="Leg1_Pitch3" type="continuous">
  <origin xyz="-0.003005 -0.060789 -0.048618" rpy="0 0 0"/>
  <parent link="Leg1_PitchLink2_2"/>
  <child link="Leg1_SteeringLink3_2"/>
  <axis xyz="0.561195 0.827684 -0.0"/>
</joint>

<joint name="Leg2_Pitch2" type="continuous">
  <origin xyz="0.242891 0.159105 0.33059" rpy="0 0 0"/>
  <parent link="Leg2_RollLink2_2"/>
  <child link="Leg2_PitchLink2_2"/>
  <axis xyz="0.64088 -0.760441 -0.104886"/>
</joint>

<joint name="Leg2_Roll3" type="continuous">
  <origin xyz="0.185259 0.203485 -0.343326" rpy="0 0 0"/>
  <parent link="Leg2_PitchLink2_2"/>
  <child link="Leg2_RollLink3_2"/>
  <axis xyz="0.421042 0.462467 -0.780287"/>
</joint>

<joint name="Leg2_Pitch3" type="continuous">
  <origin xyz="0.062871 -0.008184 -0.045257" rpy="0 0 0"/>
  <parent link="Leg2_RollLink3_2"/>
  <child link="Leg2_SteeringLink3_2"/>
  <axis xyz="-0.739448 0.673213 -0.0"/>
</joint>

<joint name="Leg2_Steering" type="continuous">
  <origin xyz="-0.036972 0.033661 -0.1" rpy="0 0 0"/>
  <parent link="Leg2_SteeringLink3_2"/>
  <child link="Leg2_Ankle_2"/>
  <axis xyz="-0.0 -0.0 -1.0"/>
</joint>

<joint name="Rigid 62" type="fixed">
  <origin xyz="0.0 0.0 -0.04" rpy="0 0 0"/>
  <parent link="Leg2_Ankle_2"/>
  <child link="Leg2_WheelBody_2"/>
</joint>

<joint name="Leg2_Wheel1" type="continuous">
  <origin xyz="-0.000911 0.069994 -0.091" rpy="0 0 0"/>
  <parent link="Leg2_WheelBody_2"/>
  <child link="Leg2_Wheel1_2"/>
  <axis xyz="-0.013013 0.999915 -0.0"/>
</joint>

<joint name="Leg2_Wheel2" type="continuous">
  <origin xyz="0.000911 -0.069994 -0.091" rpy="0 0 0"/>
  <parent link="Leg2_WheelBody_2"/>
  <child link="Leg2_Wheel2_2"/>
  <axis xyz="0.013013 -0.999915 0.0"/>
</joint>

<joint name="Rigid 65" type="fixed">
  <origin xyz="-0.328251 -0.000459 0.129376" rpy="0 0 0"/>
  <parent link="base_link"/>
  <child link="Leg3_Hip_2"/>
</joint>

<joint name="Leg3_Roll1" type="continuous">
  <origin xyz="-0.037713 0.0 -0.013333" rpy="0 0 0"/>
  <parent link="Leg3_Hip_2"/>
  <child link="Leg3_RollLink1_2"/>
  <axis xyz="-0.942809 -0.0 -0.333333"/>
</joint>

<joint name="Leg3_Pitch1" type="continuous">
  <origin xyz="-0.094281 0.049998 -0.033334" rpy="0 0 0"/>
  <parent link="Leg3_RollLink1_2"/>
  <child link="Leg3_PitchLink1_2"/>
  <axis xyz="-0.0 1.0 0.0"/>
</joint>

<joint name="Leg3_Roll2" type="continuous">
  <origin xyz="-0.039913 -0.05 0.044799" rpy="0 0 0"/>
  <parent link="Leg3_PitchLink1_2"/>
  <child link="Leg3_RollLink2_2"/>
  <axis xyz="-0.665222 -0.0 0.746646"/>
</joint>

<joint name="Leg3_Pitch2" type="continuous">
  <origin xyz="-0.292698 0.0 0.328524" rpy="0 0 0"/>
  <parent link="Leg3_RollLink2_2"/>
  <child link="Leg3_PitchLink2_2"/>
  <axis xyz="-0.0 1.0 0.0"/>
</joint>

<joint name="Leg3_Roll3" type="continuous">
  <origin xyz="-0.277575 0.0 -0.341397" rpy="0 0 0"/>
  <parent link="Leg3_PitchLink2_2"/>
  <child link="Leg3_RollLink3_2"/>
  <axis xyz="-0.630854 0.0 -0.775902"/>
</joint>

<joint name="Leg3_Pitch3" type="continuous">
  <origin xyz="-0.03659 -0.052 -0.045002" rpy="0 0 0"/>
  <parent link="Leg3_RollLink3_2"/>
  <child link="Leg3_SteeringLink_2"/>
  <axis xyz="0.0 1.0 -0.0"/>
</joint>

<joint name="Leg3_Steering" type="continuous">
  <origin xyz="0.0 0.05 -0.1" rpy="0 0 0"/>
  <parent link="Leg3_SteeringLink_2"/>
  <child link="Leg3_Ankle_2"/>
  <axis xyz="-0.0 -0.0 -1.0"/>
</joint>

<joint name="Rigid 73" type="fixed">
  <origin xyz="0.0 0.0 -0.04" rpy="0 0 0"/>
  <parent link="Leg3_Ankle_2"/>
  <child link="Wheel_body_v9_2"/>
</joint>

<joint name="Leg3_Wheel1" type="continuous">
  <origin xyz="0.0 -0.07 -0.091" rpy="0 0 0"/>
  <parent link="Wheel_body_v9_2"/>
  <child link="Wheel_v7__1__2"/>
  <axis xyz="-0.0 -1.0 0.0"/>
</joint>

<joint name="Leg3_Wheel2" type="continuous">
  <origin xyz="0.0 0.07 -0.091" rpy="0 0 0"/>
  <parent link="Wheel_body_v9_2"/>
  <child link="Wheel_v7_2"/>
  <axis xyz="0.0 1.0 -0.0"/>
</joint>

<joint name="Leg1_Roll3" type="continuous">
  <origin xyz="0.198586 -0.134647 -0.368828" rpy="0 0 0"/>
  <parent link="Leg1_PitchRollLink3_2"/>
  <child link="Leg1_PitchLink2_2"/>
  <axis xyz="0.451332 -0.306017 -0.838244"/>
</joint>

</robot>
